[2024-12-22T15:07:30.262+0000] {local_task_job_runner.py:123} INFO - ::group::Pre task execution logs
[2024-12-22T15:07:30.292+0000] {taskinstance.py:2613} INFO - Dependencies all met for dep_context=non-requeueable deps ti=<TaskInstance: dag_top_best_sellers_books.fetch_books_data manual__2024-12-22T14:55:10.356955+00:00 [queued]>
[2024-12-22T15:07:30.304+0000] {taskinstance.py:2613} INFO - Dependencies all met for dep_context=requeueable deps ti=<TaskInstance: dag_top_best_sellers_books.fetch_books_data manual__2024-12-22T14:55:10.356955+00:00 [queued]>
[2024-12-22T15:07:30.307+0000] {taskinstance.py:2866} INFO - Starting attempt 3 of 4
[2024-12-22T15:07:30.322+0000] {taskinstance.py:2889} INFO - Executing <Task(PythonOperator): fetch_books_data> on 2024-12-22 14:55:10.356955+00:00
[2024-12-22T15:07:30.333+0000] {warnings.py:112} WARNING - /home/***/.local/lib/python3.12/site-packages/***/task/task_runner/standard_task_runner.py:70: DeprecationWarning: This process (pid=310) is multi-threaded, use of fork() may lead to deadlocks in the child.
  pid = os.fork()

[2024-12-22T15:07:30.343+0000] {standard_task_runner.py:72} INFO - Started process 312 to run task
[2024-12-22T15:07:30.341+0000] {standard_task_runner.py:104} INFO - Running: ['***', 'tasks', 'run', 'dag_top_best_sellers_books', 'fetch_books_data', 'manual__2024-12-22T14:55:10.356955+00:00', '--job-id', '19', '--raw', '--subdir', 'DAGS_FOLDER/dag_test.py', '--cfg-path', '/tmp/tmp3vy8b9j6']
[2024-12-22T15:07:30.350+0000] {standard_task_runner.py:105} INFO - Job 19: Subtask fetch_books_data
[2024-12-22T15:07:30.767+0000] {task_command.py:467} INFO - Running <TaskInstance: dag_top_best_sellers_books.fetch_books_data manual__2024-12-22T14:55:10.356955+00:00 [running]> on host c50092bbd7fa
[2024-12-22T15:07:30.959+0000] {taskinstance.py:3132} INFO - Exporting env vars: AIRFLOW_CTX_DAG_OWNER='***' AIRFLOW_CTX_DAG_ID='dag_top_best_sellers_books' AIRFLOW_CTX_TASK_ID='fetch_books_data' AIRFLOW_CTX_EXECUTION_DATE='2024-12-22T14:55:10.356955+00:00' AIRFLOW_CTX_TRY_NUMBER='3' AIRFLOW_CTX_DAG_RUN_ID='manual__2024-12-22T14:55:10.356955+00:00'
[2024-12-22T15:07:30.964+0000] {taskinstance.py:731} INFO - ::endgroup::
[2024-12-22T15:08:09.704+0000] {job.py:229} INFO - Heartbeat recovered after 15.91 seconds
[2024-12-22T15:08:30.938+0000] {timeout.py:68} ERROR - Process timed out, PID: 312
[2024-12-22T15:08:32.647+0000] {taskinstance.py:3311} ERROR - Task failed with exception
Traceback (most recent call last):
  File "/home/airflow/.local/lib/python3.12/site-packages/airflow/models/taskinstance.py", line 762, in _execute_task
    result = _execute_callable(context=context, **execute_callable_kwargs)
             ^^^^^^^^^^^^^^^^^^^^^^^^^^^^^^^^^^^^^^^^^^^^^^^^^^^^^^^^^^^^^
  File "/home/airflow/.local/lib/python3.12/site-packages/airflow/models/taskinstance.py", line 733, in _execute_callable
    return ExecutionCallableRunner(
           ^^^^^^^^^^^^^^^^^^^^^^^^
  File "/home/airflow/.local/lib/python3.12/site-packages/airflow/utils/operator_helpers.py", line 252, in run
    return self.func(*args, **kwargs)
           ^^^^^^^^^^^^^^^^^^^^^^^^^^
  File "/home/airflow/.local/lib/python3.12/site-packages/airflow/models/baseoperator.py", line 422, in wrapper
    return func(self, *args, **kwargs)
           ^^^^^^^^^^^^^^^^^^^^^^^^^^^
  File "/home/airflow/.local/lib/python3.12/site-packages/airflow/operators/python.py", line 238, in execute
    return_value = self.execute_callable()
                   ^^^^^^^^^^^^^^^^^^^^^^^
  File "/home/airflow/.local/lib/python3.12/site-packages/airflow/operators/python.py", line 256, in execute_callable
    return runner.run(*self.op_args, **self.op_kwargs)
           ^^^^^^^^^^^^^^^^^^^^^^^^^^^^^^^^^^^^^^^^^^^
  File "/home/airflow/.local/lib/python3.12/site-packages/airflow/utils/operator_helpers.py", line 252, in run
    return self.func(*args, **kwargs)
           ^^^^^^^^^^^^^^^^^^^^^^^^^^
  File "/opt/airflow/dags/dag_test.py", line 28, in fetch_books_from_api
    response = requests.get(url)
               ^^^^^^^^^^^^^^^^^
  File "/home/airflow/.local/lib/python3.12/site-packages/requests/api.py", line 73, in get
    return request("get", url, params=params, **kwargs)
           ^^^^^^^^^^^^^^^^^^^^^^^^^^^^^^^^^^^^^^^^^^^^
  File "/home/airflow/.local/lib/python3.12/site-packages/requests/api.py", line 59, in request
    return session.request(method=method, url=url, **kwargs)
           ^^^^^^^^^^^^^^^^^^^^^^^^^^^^^^^^^^^^^^^^^^^^^^^^^
  File "/home/airflow/.local/lib/python3.12/site-packages/requests/sessions.py", line 589, in request
    resp = self.send(prep, **send_kwargs)
           ^^^^^^^^^^^^^^^^^^^^^^^^^^^^^^
  File "/home/airflow/.local/lib/python3.12/site-packages/requests/sessions.py", line 703, in send
    r = adapter.send(request, **kwargs)
        ^^^^^^^^^^^^^^^^^^^^^^^^^^^^^^^
  File "/home/airflow/.local/lib/python3.12/site-packages/requests/adapters.py", line 667, in send
    resp = conn.urlopen(
           ^^^^^^^^^^^^^
  File "/home/airflow/.local/lib/python3.12/site-packages/urllib3/connectionpool.py", line 789, in urlopen
    response = self._make_request(
               ^^^^^^^^^^^^^^^^^^^
  File "/home/airflow/.local/lib/python3.12/site-packages/urllib3/connectionpool.py", line 536, in _make_request
    response = conn.getresponse()
               ^^^^^^^^^^^^^^^^^^
  File "/home/airflow/.local/lib/python3.12/site-packages/urllib3/connection.py", line 507, in getresponse
    httplib_response = super().getresponse()
                       ^^^^^^^^^^^^^^^^^^^^^
  File "/usr/local/lib/python3.12/http/client.py", line 1428, in getresponse
    response.begin()
  File "/usr/local/lib/python3.12/http/client.py", line 331, in begin
    version, status, reason = self._read_status()
                              ^^^^^^^^^^^^^^^^^^^
  File "/usr/local/lib/python3.12/http/client.py", line 292, in _read_status
    line = str(self.fp.readline(_MAXLINE + 1), "iso-8859-1")
               ^^^^^^^^^^^^^^^^^^^^^^^^^^^^^^
  File "/usr/local/lib/python3.12/socket.py", line 720, in readinto
    return self._sock.recv_into(b)
           ^^^^^^^^^^^^^^^^^^^^^^^
  File "/home/airflow/.local/lib/python3.12/site-packages/airflow/utils/timeout.py", line 69, in handle_timeout
    raise AirflowTaskTimeout(self.error_message)
airflow.exceptions.AirflowTaskTimeout: Timeout, PID: 312
[2024-12-22T15:08:34.130+0000] {taskinstance.py:1225} INFO - Marking task as UP_FOR_RETRY. dag_id=dag_top_best_sellers_books, task_id=fetch_books_data, run_id=manual__2024-12-22T14:55:10.356955+00:00, execution_date=20241222T145510, start_date=20241222T150730, end_date=20241222T150834
[2024-12-22T15:08:36.516+0000] {taskinstance.py:340} INFO - ::group::Post task execution logs
[2024-12-22T15:08:40.860+0000] {local_task_job_runner.py:266} INFO - Task exited with return code 2
[2024-12-22T15:08:41.357+0000] {taskinstance.py:3895} INFO - 0 downstream tasks scheduled from follow-on schedule check
[2024-12-22T15:08:41.388+0000] {local_task_job_runner.py:245} INFO - ::endgroup::
