[2024-12-22T17:27:25.745+0000] {local_task_job_runner.py:123} INFO - ::group::Pre task execution logs
[2024-12-22T17:27:25.771+0000] {taskinstance.py:2613} INFO - Dependencies all met for dep_context=non-requeueable deps ti=<TaskInstance: dag_top_best_sellers_books.transform_books_data manual__2024-12-22T14:55:10.356955+00:00 [queued]>
[2024-12-22T17:27:25.783+0000] {taskinstance.py:2613} INFO - Dependencies all met for dep_context=requeueable deps ti=<TaskInstance: dag_top_best_sellers_books.transform_books_data manual__2024-12-22T14:55:10.356955+00:00 [queued]>
[2024-12-22T17:27:25.786+0000] {taskinstance.py:2866} INFO - Starting attempt 13 of 14
[2024-12-22T17:27:25.806+0000] {taskinstance.py:2889} INFO - Executing <Task(PythonOperator): transform_books_data> on 2024-12-22 14:55:10.356955+00:00
[2024-12-22T17:27:25.816+0000] {warnings.py:112} WARNING - /home/***/.local/lib/python3.12/site-packages/***/task/task_runner/standard_task_runner.py:70: DeprecationWarning: This process (pid=1613) is multi-threaded, use of fork() may lead to deadlocks in the child.
  pid = os.fork()

[2024-12-22T17:27:25.822+0000] {standard_task_runner.py:72} INFO - Started process 1615 to run task
[2024-12-22T17:27:25.820+0000] {standard_task_runner.py:104} INFO - Running: ['***', 'tasks', 'run', 'dag_top_best_sellers_books', 'transform_books_data', 'manual__2024-12-22T14:55:10.356955+00:00', '--job-id', '49', '--raw', '--subdir', 'DAGS_FOLDER/dag_test.py', '--cfg-path', '/tmp/tmpzny3rkzb']
[2024-12-22T17:27:25.828+0000] {standard_task_runner.py:105} INFO - Job 49: Subtask transform_books_data
[2024-12-22T17:27:26.138+0000] {task_command.py:467} INFO - Running <TaskInstance: dag_top_best_sellers_books.transform_books_data manual__2024-12-22T14:55:10.356955+00:00 [running]> on host c50092bbd7fa
[2024-12-22T17:27:26.257+0000] {taskinstance.py:3132} INFO - Exporting env vars: AIRFLOW_CTX_DAG_OWNER='***' AIRFLOW_CTX_DAG_ID='dag_top_best_sellers_books' AIRFLOW_CTX_TASK_ID='transform_books_data' AIRFLOW_CTX_EXECUTION_DATE='2024-12-22T14:55:10.356955+00:00' AIRFLOW_CTX_TRY_NUMBER='13' AIRFLOW_CTX_DAG_RUN_ID='manual__2024-12-22T14:55:10.356955+00:00'
[2024-12-22T17:27:26.262+0000] {taskinstance.py:731} INFO - ::endgroup::
[2024-12-22T17:27:26.326+0000] {taskinstance.py:3311} ERROR - Task failed with exception
Traceback (most recent call last):
  File "/home/airflow/.local/lib/python3.12/site-packages/airflow/models/taskinstance.py", line 767, in _execute_task
    result = _execute_callable(context=context, **execute_callable_kwargs)
             ^^^^^^^^^^^^^^^^^^^^^^^^^^^^^^^^^^^^^^^^^^^^^^^^^^^^^^^^^^^^^
  File "/home/airflow/.local/lib/python3.12/site-packages/airflow/models/taskinstance.py", line 733, in _execute_callable
    return ExecutionCallableRunner(
           ^^^^^^^^^^^^^^^^^^^^^^^^
  File "/home/airflow/.local/lib/python3.12/site-packages/airflow/utils/operator_helpers.py", line 252, in run
    return self.func(*args, **kwargs)
           ^^^^^^^^^^^^^^^^^^^^^^^^^^
  File "/home/airflow/.local/lib/python3.12/site-packages/airflow/models/baseoperator.py", line 422, in wrapper
    return func(self, *args, **kwargs)
           ^^^^^^^^^^^^^^^^^^^^^^^^^^^
  File "/home/airflow/.local/lib/python3.12/site-packages/airflow/operators/python.py", line 238, in execute
    return_value = self.execute_callable()
                   ^^^^^^^^^^^^^^^^^^^^^^^
  File "/home/airflow/.local/lib/python3.12/site-packages/airflow/operators/python.py", line 256, in execute_callable
    return runner.run(*self.op_args, **self.op_kwargs)
           ^^^^^^^^^^^^^^^^^^^^^^^^^^^^^^^^^^^^^^^^^^^
  File "/home/airflow/.local/lib/python3.12/site-packages/airflow/utils/operator_helpers.py", line 252, in run
    return self.func(*args, **kwargs)
           ^^^^^^^^^^^^^^^^^^^^^^^^^^
  File "/opt/airflow/dags/dag_test.py", line 45, in transform_books_data
    transformed_data = transform_data(book_data,logger)
                       ^^^^^^^^^^^^^^^^^^^^^^^^^^^^^^^^
  File "/opt/airflow/dags/scripts/transform_data.py", line 28, in transform_data
    .merge(date_dim, how='left', left_on='Date', right_on='Date')
     ^^^^^^^^^^^^^^^^^^^^^^^^^^^^^^^^^^^^^^^^^^^^^^^^^^^^^^^^^^^^
  File "/home/airflow/.local/lib/python3.12/site-packages/pandas/core/frame.py", line 10487, in merge
    return merge(
           ^^^^^^
  File "/home/airflow/.local/lib/python3.12/site-packages/pandas/core/reshape/merge.py", line 169, in merge
    op = _MergeOperation(
         ^^^^^^^^^^^^^^^^
  File "/home/airflow/.local/lib/python3.12/site-packages/pandas/core/reshape/merge.py", line 804, in __init__
    self._maybe_coerce_merge_keys()
  File "/home/airflow/.local/lib/python3.12/site-packages/pandas/core/reshape/merge.py", line 1483, in _maybe_coerce_merge_keys
    raise ValueError(msg)
ValueError: You are trying to merge on datetime64[ns] and object columns for key 'Date'. If you wish to proceed you should use pd.concat
[2024-12-22T17:27:26.366+0000] {taskinstance.py:1225} INFO - Marking task as UP_FOR_RETRY. dag_id=dag_top_best_sellers_books, task_id=transform_books_data, run_id=manual__2024-12-22T14:55:10.356955+00:00, execution_date=20241222T145510, start_date=20241222T172725, end_date=20241222T172726
[2024-12-22T17:27:26.407+0000] {taskinstance.py:340} INFO - ::group::Post task execution logs
[2024-12-22T17:27:26.411+0000] {standard_task_runner.py:124} ERROR - Failed to execute job 49 for task transform_books_data (You are trying to merge on datetime64[ns] and object columns for key 'Date'. If you wish to proceed you should use pd.concat; 1615)
Traceback (most recent call last):
  File "/home/airflow/.local/lib/python3.12/site-packages/airflow/task/task_runner/standard_task_runner.py", line 117, in _start_by_fork
    ret = args.func(args, dag=self.dag)
          ^^^^^^^^^^^^^^^^^^^^^^^^^^^^^
  File "/home/airflow/.local/lib/python3.12/site-packages/airflow/cli/cli_config.py", line 49, in command
    return func(*args, **kwargs)
           ^^^^^^^^^^^^^^^^^^^^^
  File "/home/airflow/.local/lib/python3.12/site-packages/airflow/utils/cli.py", line 116, in wrapper
    return f(*args, **kwargs)
           ^^^^^^^^^^^^^^^^^^
  File "/home/airflow/.local/lib/python3.12/site-packages/airflow/cli/commands/task_command.py", line 483, in task_run
    task_return_code = _run_task_by_selected_method(args, _dag, ti)
                       ^^^^^^^^^^^^^^^^^^^^^^^^^^^^^^^^^^^^^^^^^^^^
  File "/home/airflow/.local/lib/python3.12/site-packages/airflow/cli/commands/task_command.py", line 256, in _run_task_by_selected_method
    return _run_raw_task(args, ti)
           ^^^^^^^^^^^^^^^^^^^^^^^
  File "/home/airflow/.local/lib/python3.12/site-packages/airflow/cli/commands/task_command.py", line 341, in _run_raw_task
    return ti._run_raw_task(
           ^^^^^^^^^^^^^^^^^
  File "/home/airflow/.local/lib/python3.12/site-packages/airflow/utils/session.py", line 97, in wrapper
    return func(*args, session=session, **kwargs)
           ^^^^^^^^^^^^^^^^^^^^^^^^^^^^^^^^^^^^^^
  File "/home/airflow/.local/lib/python3.12/site-packages/airflow/models/taskinstance.py", line 3005, in _run_raw_task
    return _run_raw_task(
           ^^^^^^^^^^^^^^
  File "/home/airflow/.local/lib/python3.12/site-packages/airflow/models/taskinstance.py", line 273, in _run_raw_task
    TaskInstance._execute_task_with_callbacks(
  File "/home/airflow/.local/lib/python3.12/site-packages/airflow/models/taskinstance.py", line 3159, in _execute_task_with_callbacks
    result = self._execute_task(context, task_orig)
             ^^^^^^^^^^^^^^^^^^^^^^^^^^^^^^^^^^^^^^
  File "/home/airflow/.local/lib/python3.12/site-packages/airflow/models/taskinstance.py", line 3183, in _execute_task
    return _execute_task(self, context, task_orig)
           ^^^^^^^^^^^^^^^^^^^^^^^^^^^^^^^^^^^^^^^
  File "/home/airflow/.local/lib/python3.12/site-packages/airflow/models/taskinstance.py", line 767, in _execute_task
    result = _execute_callable(context=context, **execute_callable_kwargs)
             ^^^^^^^^^^^^^^^^^^^^^^^^^^^^^^^^^^^^^^^^^^^^^^^^^^^^^^^^^^^^^
  File "/home/airflow/.local/lib/python3.12/site-packages/airflow/models/taskinstance.py", line 733, in _execute_callable
    return ExecutionCallableRunner(
           ^^^^^^^^^^^^^^^^^^^^^^^^
  File "/home/airflow/.local/lib/python3.12/site-packages/airflow/utils/operator_helpers.py", line 252, in run
    return self.func(*args, **kwargs)
           ^^^^^^^^^^^^^^^^^^^^^^^^^^
  File "/home/airflow/.local/lib/python3.12/site-packages/airflow/models/baseoperator.py", line 422, in wrapper
    return func(self, *args, **kwargs)
           ^^^^^^^^^^^^^^^^^^^^^^^^^^^
  File "/home/airflow/.local/lib/python3.12/site-packages/airflow/operators/python.py", line 238, in execute
    return_value = self.execute_callable()
                   ^^^^^^^^^^^^^^^^^^^^^^^
  File "/home/airflow/.local/lib/python3.12/site-packages/airflow/operators/python.py", line 256, in execute_callable
    return runner.run(*self.op_args, **self.op_kwargs)
           ^^^^^^^^^^^^^^^^^^^^^^^^^^^^^^^^^^^^^^^^^^^
  File "/home/airflow/.local/lib/python3.12/site-packages/airflow/utils/operator_helpers.py", line 252, in run
    return self.func(*args, **kwargs)
           ^^^^^^^^^^^^^^^^^^^^^^^^^^
  File "/opt/airflow/dags/dag_test.py", line 45, in transform_books_data
    transformed_data = transform_data(book_data,logger)
                       ^^^^^^^^^^^^^^^^^^^^^^^^^^^^^^^^
  File "/opt/airflow/dags/scripts/transform_data.py", line 28, in transform_data
    .merge(date_dim, how='left', left_on='Date', right_on='Date')
     ^^^^^^^^^^^^^^^^^^^^^^^^^^^^^^^^^^^^^^^^^^^^^^^^^^^^^^^^^^^^
  File "/home/airflow/.local/lib/python3.12/site-packages/pandas/core/frame.py", line 10487, in merge
    return merge(
           ^^^^^^
  File "/home/airflow/.local/lib/python3.12/site-packages/pandas/core/reshape/merge.py", line 169, in merge
    op = _MergeOperation(
         ^^^^^^^^^^^^^^^^
  File "/home/airflow/.local/lib/python3.12/site-packages/pandas/core/reshape/merge.py", line 804, in __init__
    self._maybe_coerce_merge_keys()
  File "/home/airflow/.local/lib/python3.12/site-packages/pandas/core/reshape/merge.py", line 1483, in _maybe_coerce_merge_keys
    raise ValueError(msg)
ValueError: You are trying to merge on datetime64[ns] and object columns for key 'Date'. If you wish to proceed you should use pd.concat
[2024-12-22T17:27:26.459+0000] {local_task_job_runner.py:266} INFO - Task exited with return code 1
[2024-12-22T17:27:26.684+0000] {taskinstance.py:3895} INFO - 0 downstream tasks scheduled from follow-on schedule check
[2024-12-22T17:27:26.691+0000] {local_task_job_runner.py:245} INFO - ::endgroup::
